Workbook

Sheet Preview
A1: AHP (Analytical Hierarchy Process)
A2: Termasuk dalam MADM (Multi Atribute Decision Making)
A4: 3 Tujuan identifikasi (HIERARCHY)
A5: - Tentukan Tujuan
A6: - Tentukan Kriteria
A7: - Tentukan Alternatif
A9: DITENTUKAN OLEH SELF JUDGEMENT
A11: 9 -= MUTLAK
A12: 7 = SANGAT LEBIH PENTING
A13: 5 = LEBIH PENTING
A14: 3 = CUKUP PENTING
A15: 1 = SAMA PENTING
A16: 2, 4, 6, 8 = INTERVAL ANTAR PREFERENSI BERNILAI KUAT

Sheet MATRIKS PERBANDINGAN
A2: ALTERNATIF (MEREK) | B2: HARGA | C2: BATERAI (mAh) | D2: RAM (GB) | E2: STORAGE (GB) | F2: KAMERA (MP)
A3: Apple | B3: 2800000 | C3: 6000 | D3: 4 | E3: 64 | F3: 48
A4: Oppo | B4: 2100000 | C4: 5020 | D4: 3 | E4: 64 | F4: 48
A5: Vivo | B5: 2200000 | C5: 5000 | D5: 4 | E5: 128 | F5: 13
A6: Samsung | B6: 2500000 | C6: 4230 | D6: 4 | E6: 128 | F6: 12
A8: Ketentuan: Harga, ROM, Kamera, Baterai | F8: HARGA | G8: BATERAI | H8: RAM | I8: STORAGE | J8: KAMERA
A9: 9 = MUTLAK (EXTREME) | E9: HARGA | F9: 1 | G9: 5 | H9: 5 | I9: 5 | J9: 3
A10: 7 = SANGAT LEBIH PENTING (VERY) | E10: BATERAI | F10: 45778 | G10: 1 | H10: 1 | I10: 1 | J10: 45717
A11: 5 = LEBIH PENTING (STRONG) | E11: RAM | F11: 45778 | G11: 1 | H11: 1 | I11: 1 | J11: 45717
A12: 3 = CUKUP PENTING (MODERATE) | E12: STORAGE | F12: 45778 | G12: 1 | H12: 1 | I12: 1 | J12: 45717
A13: 1 = SAMA PENTING (EQUAL) | E13: KAMERA | F13: 45717 | G13: 3 | H13: 3 | I13: 3 | J13: 1
A14: 2, 4, 6, 8 = INTERVAL ANTAR PREFERENSI BERNILAI KUAT
E15: RI
E16: 1 | F16: 2 | G16: 3 | H16: 4 | I16: 5 | J16: 6 | K16: 7
E17: 0 | F17: 0 | G17: 0.58 | H17: 0.9 | I17: 1.12 | J17: 1.24 | K17: 1.32

Sheet KRITERIA UTAMA
A2: ALTERNATIF (MEREK) | B2: HARGA | C2: BATERAI (mAh) | D2: RAM (GB) | E2: STORAGE (GB) | F2: KAMERA (MP)
A3: Apple | B3: 2800000 | C3: 6000 | D3: 4 | E3: 64 | F3: 48
A4: Oppo | B4: 2100000 | C4: 5020 | D4: 3 | E4: 64 | F4: 48
A5: Vivo | B5: 2200000 | C5: 5000 | D5: 4 | E5: 128 | F5: 13
A6: Samsung | B6: 2500000 | C6: 4230 | D6: 4 | E6: 128 | F6: 12
A7: Ketentuan: Harga, ROM, RAM, Kamera, Baterai
B9: Harga | C9: Memori | D9: RAM | E9: Kamera | F9: Baterai
A10: H | B10: 1 | C10: 5 | D10: 5 | E10: 5 | F10: 3
A11: M | B11: 45778 | C11: 1 | D11: 1 | E11: 1 | F11: 45717
A12: R | B12: 45778 | C12: 1 | D12: 1 | E12: 1 | F12: 45717
A13: K | B13: 45778 | C13: 1 | D13: 1 | E13: 1 | F13: 45717
A14: B | B14: 45717 | C14: 3 | D14: 3 | E14: 3 | F14: 1
A16: 2. Membuat Matrix Perbandingan
B17: Harga | C17: Memori | D17: RAM | E17: Kamera | F17: Baterai
A18: H | B18: 1 | C18: 5 | D18: 5 | E18: 5 | F18: 3
A19: M | B19: =1/5 -> 0.2 | C19: 1 | D19: 1 | E19: 1 | F19: =1/3 -> 0.33333333
A20: R | B20: =1/5 -> 0.2 | C20: 1 | D20: 1 | E20: 1 | F20: =1/3 -> 0.33333333
A21: K | B21: =1/5 -> 0.2 | C21: 1 | D21: 1 | E21: 1 | F21: =1/3 -> 0.33333333
A22: B | B22: =1/3 -> 0.33333333 | C22: 3 | D22: 3 | E22: 3 | F22: 1
A23: JUMLAH | B23: =sum(B18:B22) -> 1.9333333 | C23: =SUM(C18:C22) -> 11 | D23: =SUM(D18:D22) -> 11 | E23: =SUM(E18:E22) -> 11 | F23: =SUM(F18:F22) -> 5
A25: 3. Menentukan Nilai Eigen dengan membagi setiap matrix dengan jumlah
B26: Harga | C26: Memori | D26: RAM | E26: Kamera | F26: Baterai | G26: Jumlah | H26: Rata-rata nilai eigen
A27: H | B27: =B18/$B$23 -> 0.51724138 | C27: =C18/$C$23 -> 0.45454545 | D27: =D18/$D$23 -> 0.45454545 | E27: =E18/$E$23 -> 0.45454545 | F27: =F18/$F$23 -> 0.6 | G27: =sum(B27:F27) -> 2.4808777 | H27: =AVERAGE(B27:F27) -> 0.49617555
A28: M | B28: =B19/$B$23 -> 0.10344828 | C28: =C19/$C$23 -> 0.090909091 | D28: =D19/$D$23 -> 0.090909091 | E28: =E19/$E$23 -> 0.090909091 | F28: =F19/$F$23 -> 0.066666667 | G28: =sum(B28:F28) -> 0.44284222 | H28: =AVERAGE(B28:F28) -> 0.088568443
A29: R | B29: =B20/$B$23 -> 0.10344828 | C29: =C20/$C$23 -> 0.090909091 | D29: =D20/$D$23 -> 0.090909091 | E29: =E20/$E$23 -> 0.090909091 | F29: =F20/$F$23 -> 0.066666667 | G29: =sum(B29:F29) -> 0.44284222 | H29: =AVERAGE(B29:F29) -> 0.088568443
A30: K | B30: =B21/$B$23 -> 0.10344828 | C30: =C21/$C$23 -> 0.090909091 | D30: =D21/$D$23 -> 0.090909091 | E30: =E21/$E$23 -> 0.090909091 | F30: =F21/$F$23 -> 0.066666667 | G30: =sum(B30:F30) -> 0.44284222 | H30: =AVERAGE(B30:F30) -> 0.088568443
A31: B | B31: =B22/$B$23 -> 0.17241379 | C31: =C22/$C$23 -> 0.27272727 | D31: =D22/$D$23 -> 0.27272727 | E31: =E22/$E$23 -> 0.27272727 | F31: =F22/$F$23 -> 0.2 | G31: =sum(B31:F31) -> 1.1905956 | H31: =AVERAGE(B31:F31) -> 0.23811912
A32: JUMLAH | B32: =sum(B27:B31) -> 1 | C32: =SUM(C27:C31) -> 1 | D32: =D23/$D$23 -> 1 | E32: =SUM(E27:E31) -> 1 | F32: =SUM(F27:F31) -> 1 | G32: =sum(B32:F32) -> 5 | H32: =AVERAGE(B32:F32) -> 1
A34: 4. Normalisasi Nilai Konsistensi (CI)
B35: Harga | C35: Memori | D35: RAM | E35: Kamera | F35: Baterai | G35: Normalisasi
A36: H | B36: 1 | C36: 5 | D36: 5 | E36: 5 | F36: 3 | G36: =(B36*$H$27)+(C36*$H$28)+(D36*$H$29)+(E36*$H$30)+(F36*$H$31) -> 2.5390596
A37: M | B37: =1/5 -> 0.2 | C37: 1 | D37: 1 | E37: 1 | F37: =1/3 -> 0.33333333 | G37: =(B37*$H$27)+(C37*$H$28)+(D37*$H$29)+(E37*$H$30)+(F37*$H$31) -> 0.44431348
A38: R | B38: =1/5 -> 0.2 | C38: 1 | D38: 1 | E38: 1 | F38: =1/3 -> 0.33333333 | G38: =(B38*$H$27)+(C38*$H$28)+(D38*$H$29)+(E38*$H$30)+(F38*$H$31) -> 0.44431348
A39: K | B39: =1/5 -> 0.2 | C39: 1 | D39: 1 | E39: 1 | F39: =1/3 -> 0.33333333 | G39: =(B39*$H$27)+(C39*$H$28)+(D39*$H$29)+(E39*$H$30)+(F39*$H$31) -> 0.44431348
A40: B | B40: =1/3 -> 0.33333333 | C40: 3 | D40: 3 | E40: 3 | F40: 1 | G40: =(B40*$H$27)+(C40*$H$28)+(D40*$H$29)+(E40*$H$30)+(F40*$H$31) -> 1.200627
A41: JUMLAH | B41: =sum(B36:B40) -> 1.9333333 | C41: =SUM(C36:C40) -> 11 | D41: =SUM(D36:D40) -> 11 | E41: =SUM(E36:E40) -> 11 | F41: =SUM(F36:F40) -> 5
A43: 5. Menghitung Nilai Konsistensi
A44: Lamda Max | B44: =((G36/H27)+(G37/H28)+(G38/H29)+(G39/H30)+(G40/H31))/5 -> 5.0418446
A45: Cl | B45: =(B44-5)/(5-1) -> 0.010461141
A46: IR | B46: ='MATRIKS PERBANDINGAN'!I17 -> 1.12
...

Sheet HARGA
A2: ALTERNATIF (MEREK) | B2: HARGA | C2: BATERAI (mAh) | D2: RAM (GB) | E2: STORAGE (GB) | F2: KAMERA (MP)
A3: Apple | B3: 2800000 | C3: 6000 | D3: 4 | E3: 64 | F3: 48
A4: Oppo | B4: 2100000 | C4: 5020 | D4: 3 | E4: 64 | F4: 48
A5: Vivo | B5: 2200000 | C5: 5000 | D5: 4 | E5: 128 | F5: 13
A6: Samsung | B6: 2500000 | C6: 4230 | D6: 4 | E6: 128 | F6: 12
A7: Ketentuan: Harga, ROM, RAM, Kamera, Baterai
A9: Matriks
B10: Apple | C10: Oppo | D10: Vivo | E10: Samsung
A11: Apple | B11: 1 | C11: 45839 | D11: 45809 | E11: 45717
A12: Oppo | B12: 7 | C12: 1 | D12: 2 | E12: 3
A13: Vivo | B13: 6 | C13: 45689 | D13: 1 | E13: 3
A14: Samsung | B14: 3 | C14: 45717 | D14: 45717 | E14: 1
A16: Matriks Perbandingan
B17: Apple | C17: Oppo | D17: Vivo | E17: Samsung
A18: Apple | B18: 1 | C18: =1/7 -> 0.14285714 | D18: =1/6 -> 0.16666667 | E18: =1/3 -> 0.33333333
A19: Oppo | B19: 7 | C19: 1 | D19: 2 | E19: 3
A20: Vivo | B20: 6 | C20: =1/2 -> 0.5 | D20: 1 | E20: 3
A21: Samsung | B21: 3 | C21: =1/3 -> 0.33333333 | D21: =1/3 -> 0.33333333 | E21: 1
A22: Jumlah | B22: =sum(B18:B21) -> 17 | C22: =sum(C18:C21) -> 1.9761905 | D22: =sum(D18:D21) -> 3.5 | E22: =sum(E18:E21) -> 7.3333333
A24: Menentukan Nilai Eigen dengan membagi setiap matrix dengan jumlah
B25: Apple | C25: Oppo | D25: Vivo | E25: Samsung | F25: Jumlah | G25: Rata-rata nilai eigen
A26: Apple | B26: =B18/$B$22 -> 0.058823529 | C26: =C18/$C$22 -> 0.072289157 | D26: =D18/$D$22 -> 0.047619048 | E26: =E18/$E$22 -> 0.045454545 | F26: =sum(B26:E26) -> 0.22418628 | G26: =AVERAGE(B26:E26) -> 0.05604657
A27: Oppo | B27: =B19/$B$22 -> 0.41176471 | C27: =C19/$C$22 -> 0.5060241 | D27: =D19/$D$22 -> 0.57142857 | E27: =E19/$E$22 -> 0.40909091 | F27: =sum(B27:E27) -> 1.8983083 | G27: =AVERAGE(B27:E27) -> 0.47457707
A28: Vivo | B28: =B20/$B$22 -> 0.35294118 | C28: =C20/$C$22 -> 0.25301205 | D28: =D20/$D$22 -> 0.28571429 | E28: =E20/$E$22 -> 0.40909091 | F28: =sum(B28:E28) -> 1.3007584 | G28: =AVERAGE(B28:E28) -> 0.3251896
A29: Samsung | B29: =B21/$B$22 -> 0.17647059 | C29: =C21/$C$22 -> 0.1686747 | D29: =D21/$D$22 -> 0.095238095 | E29: =E21/$E$22 -> 0.13636364 | F29: =sum(B29:E29) -> 0.57674702 | G29: =AVERAGE(B29:E29) -> 0.14418675
A30: JUMLAH | B30: =sum(B26:B29) -> 1 | C30: =SUM(C26:C29) -> 1 | D30: =sum(D26:D29) -> 1 | E30: =SUM(E26:E29) -> 1 | F30: =sum(B30:E30) -> 4 | G30: =AVERAGE(B30:E30) -> 1
A32: Normalisasi Nilai Konsistensi (CI)
B33: Apple | C33: Oppo | D33: Vivo | E33: Samsung | F33: Jumlah
A34: H | B34: 1 | C34: =1/7 -> 0.14285714 | D34: =1/6 -> 0.16666667 | E34: =1/3 -> 0.33333333 | F34: =(B34*$G$26)+(C34*$G$27)+(D34*$G$28)+(E34*$G$29) -> 0.22610381
A35: M | B35: 7 | C35: 1 | D35: 2 | E35: 3 | F35: =(B35*$G$26)+(C35*$G$27)+(D35*$G$28)+(E35*$G$29) -> 1.9498425
A36: R | B36: 6 | C36: =1/3 -> 0.33333333 | D36: 1 | E36: 3 | F36: =(B36*$G$26)+(C36*$G$27)+(D36*$G$28)+(E36*$G$29) -> 1.2522216
A37: K | B37: 3 | C37: =1/3 -> 0.33333333 | D37: =1/3 -> 0.33333333 | E37: 1 | F37: =(B37*$G$26)+(C37*$G$27)+(D37*$G$28)+(E37*$G$29) -> 0.57891536
A38: JUMLAH | B38: =sum(B34:B37) -> 17 | C38: =SUM(C34:C37) -> 1.8095238 | D38: =SUM(D34:D37) -> 3.5 | E38: =SUM(E34:E37) -> 7.3333333
A40: 5. Menghitung Nilai Konsistensi
A41: Lamda Max | B41: =((F34/G26)+(F35/G27)+(F36/G28)+(F37/G29))/4 -> 4.0021462
A42: Cl | B42: =(B41-4)/(4-1) -> 0.00071538494
A43: IR | B43: ='MATRIKS PERBANDINGAN'!H17 -> 0.9
A44: CR = CI/IR | B44: =B42/B43 -> 0.00079487215

Sheet MEMORY
A2: ALTERNATIF (MEREK) | B2: HARGA | C2: BATERAI (mAh) | D2: RAM (GB) | E2: STORAGE (GB) | F2: KAMERA (MP)
A3: Apple | B3: 2800000 | C3: 6000 | D3: 4 | E3: 64 | F3: 48
A4: Oppo | B4: 2100000 | C4: 5020 | D4: 3 | E4: 64 | F4: 48
A5: Vivo | B5: 2200000 | C5: 5000 | D5: 4 | E5: 128 | F5: 13
A6: Samsung | B6: 2500000 | C6: 4230 | D6: 4 | E6: 128 | F6: 12
A7: Ketentuan: Harga, ROM, RAM, Kamera, Baterai
A9: Matriks
B10: Apple | C10: Oppo | D10: Vivo | E10: Samsung
A11: Apple | B11: 1 | C11: 1 | D11: 45689 | E11: 45689
A12: Oppo | B12: 1 | C12: 1 | D12: 45689 | E12: 45689
A13: Vivo | B13: 2 | C13: 2 | D13: 1 | E13: 1
A14: Samsung | B14: 2 | C14: 2 | D14: 1 | E14: 1
A16: Matriks Perbandingan
B17: Apple | C17: Oppo | D17: Vivo | E17: Samsung
A18: Apple | B18: 1 | C18: 1 | D18: =1/2 -> 0.5 | E18: =1/2 -> 0.5
A19: Oppo | B19: 1 | C19: 1 | D19: =1/2 -> 0.5 | E19: =1/2 -> 0.5
A20: Vivo | B20: 2 | C20: 2 | D20: 1 | E20: 1
A21: Samsung | B21: 2 | C21: 2 | D21: 1 | E21: 1
A22: Jumlah | B22: =sum(B18:B21) -> 6 | C22: =sum(C18:C21) -> 6 | D22: =sum(D18:D21) -> 3 | E22: =sum(E18:E21) -> 3
A24: Menentukan Nilai Eigen dengan membagi setiap matrix dengan jumlah
B25: Apple | C25: Oppo | D25: Vivo | E25: Samsung | F25: Jumlah | G25: Rata-rata nilai eigen
A26: Apple | B26: =B18/$B$22 -> 0.16666667 | C26: =C18/$C$22 -> 0.16666667 | D26: =D18/$D$22 -> 0.16666667 | E26: =E18/$E$22 -> 0.16666667 | F26: =sum(B26:E26) -> 0.66666667 | G26: =AVERAGE(B26:E26) -> 0.16666667
A27: Oppo | B27: =B19/$B$22 -> 0.16666667 | C27: =C19/$C$22 -> 0.16666667 | D27: =D19/$D$22 -> 0.16666667 | E27: =E19/$B$22 -> 0.083333333 | F27: =sum(B27:E27) -> 0.58333333 | G27: =AVERAGE(B27:E27) -> 0.14583333
A28: Vivo | B28: =B20/$B$22 -> 0.33333333 | C28: =C20/$C$22 -> 0.33333333 | D28: =D20/$D$22 -> 0.33333333 | E28: =E20/$B$22 -> 0.16666667 | F28: =sum(B28:E28) -> 1.1666667 | G28: =AVERAGE(B28:E28) -> 0.29166667
A29: Samsung | B29: =B21/$B$22 -> 0.33333333 | C29: =C21/$C$22 -> 0.33333333 | D29: =D21/$D$22 -> 0.33333333 | E29: =E21/$B$22 -> 0.16666667 | F29: =sum(B29:E29) -> 1.1666667 | G29: =AVERAGE(B29:E29) -> 0.29166667
A30: JUMLAH | B30: =sum(B26:B29) -> 1 | C30: =sum(C26:C29) -> 1 | D30: =sum(D26:D29) -> 1 | E30: =sum(E26:E29) -> 0.58333333 | F30: =sum(B30:E30) -> 3.5833333 | G30: =AVERAGE(B30:E30) -> 0.89583333
A32: Normalisasi Nilai Konsistensi (CI)
B33: Apple | C33: Oppo | D33: Vivo | E33: Samsung | F33: Jumlah
A34: H | B34: 1 | C34: 1 | D34: =1/2 -> 0.5 | E34: =1/2 -> 0.5 | F34: =(B34*$G$26)+(C34*$G$27)+(D34*$G$28)+(E34*$G$29) -> 0.60416667
A35: M | B35: 1 | C35: 1 | D35: =1/2 -> 0.5 | E35: =1/2 -> 0.5 | F35: =(B35*$G$26)+(C35*$G$27)+(D35*$G$28)+(E35*$G$29) -> 0.60416667
A36: R | B36: 2 | C36: 2 | D36: 1 | E36: 1 | F36: =(B36*$G$26)+(C36*$G$27)+(D36*$G$28)+(E36*$G$29) -> 1.2083333
A37: K | B37: 2 | C37: 2 | D37: 1 | E37: 1 | F37: =(B37*$G$26)+(C37*$G$27)+(D37*$G$28)+(E37*$G$29) -> 1.2083333
A38: JUMLAH | B38: =sum(B34:B37) -> 6 | C38: =sum(C34:C37) -> 6 | D38: =sum(D34:D37) -> 3 | E38: =sum(E34:E37) -> 3
A40: 5. Menghitung Nilai Konsistensi
A41: Lamda Max | B41: =((F34/G26)+(F35/G27)+(F36/G28)+(F37/G29))/4 -> 4.0133929
A42: Cl | B42: =(B41-4)/(4-1) -> 0.0044642857
A43: IR | B43: ='MATRIKS PERBANDINGAN'!H17 -> 0.9
A44: CR = CI/IR | B44: =B42/B43 -> 0.0049603175

Sheet RAM
A2: ALTERNATIF (MEREK) | B2: HARGA | C2: BATERAI (mAh) | D2: RAM (GB) | E2: STORAGE (GB) | F2: KAMERA (MP)
A3: Apple | B3: 2800000 | C3: 6000 | D3: 4 | E3: 64 | F3: 48
A4: Oppo | B4: 2100000 | C4: 5020 | D4: 3 | E4: 64 | F4: 48
A5: Vivo | B5: 2200000 | C5: 5000 | D5: 4 | E5: 128 | F5: 13
A6: Samsung | B6: 2500000 | C6: 4230 | D6: 4 | E6: 128 | F6: 12
A7: Ketentuan: Harga, ROM, RAM, Kamera, Baterai
A9: Matriks
B10: Apple | C10: Oppo | D10: Vivo | E10: Samsung
A11: Apple | B11: 1 | C11: 3 | D11: 1 | E11: 1
A12: Oppo | B12: 45717 | C12: 1 | D12: 45717 | E12: 45717
A13: Vivo | B13: 1 | C13: 3 | D13: 1 | E13: 1
A14: Samsung | B14: 1 | C14: 3 | D14: 1 | E14: 1
A16: Matriks Perbandingan
B17: Apple | C17: Oppo | D17: Vivo | E17: Samsung
A18: Apple | B18: 1 | C18: 3 | D18: 1 | E18: 1
A19: Oppo | B19: =1/3 -> 0.33333333 | C19: 1 | D19: =1/3 -> 0.33333333 | E19: =1/3 -> 0.33333333
A20: Vivo | B20: 1 | C20: 3 | D20: 1 | E20: 1
A21: Samsung | B21: 1 | C21: 3 | D21: 1 | E21: 1
A22: Jumlah | B22: =sum(B18:B21) -> 3.3333333 | C22: =sum(C18:C21) -> 10 | D22: =sum(D18:D21) -> 3.3333333 | E22: =sum(E18:E21) -> 3.3333333
A24: Menentukan Nilai Eigen dengan membagi setiap matrix dengan jumlah
B25: Apple | C25: Oppo | D25: Vivo | E25: Samsung | F25: Jumlah | G25: Rata-rata nilai eigen
A26: Apple | B26: =B18/$B$22 -> 0.3 | C26: =C18/$C$22 -> 0.3 | D26: =D18/$D$22 -> 0.3 | E26: =E18/$E$22 -> 0.3 | F26: =sum(B26:E26) -> 1.2 | G26: =AVERAGE(B26:E26) -> 0.3
A27: Oppo | B27: =B19/$B$22 -> 0.1 | C27: =C19/$C$22 -> 0.1 | D27: =D19/$D$22 -> 0.1 | E27: =E19/$E$22 -> 0.1 | F27: =sum(B27:E27) -> 0.4 | G27: =AVERAGE(B27:E27) -> 0.1
A28: Vivo | B28: =B20/$B$22 -> 0.3 | C28: =C20/$C$22 -> 0.3 | D28: =D20/$D$22 -> 0.3 | E28: =E20/$E$22 -> 0.3 | F28: =sum(B28:E28) -> 1.2 | G28: =AVERAGE(B28:E28) -> 0.3
A29: Samsung | B29: =B21/$B$22 -> 0.3 | C29: =C21/$C$22 -> 0.3 | D29: =D21/$D$22 -> 0.3 | E29: =E21/$E$22 -> 0.3 | F29: =sum(B29:E29) -> 1.2 | G29: =AVERAGE(B29:E29) -> 0.3
A30: JUMLAH | B30: =sum(B26:B29) -> 1 | C30: =C22/$C$22 -> 1 | D30: =sum(D26:D29) -> 1 | E30: =sum(E26:E29) -> 1 | F30: =sum(B30:E30) -> 4 | G30: =AVERAGE(B30:E30) -> 1
A32: Normalisasi Nilai Konsistensi (CI)
B33: Apple | C33: Oppo | D33: Vivo | E33: Samsung | F33: Jumlah
A34: H | B34: 1 | C34: 1 | D34: =1/2 -> 0.5 | E34: =1/2 -> 0.5 | F34: =(B34*$G$26)+(C34*$G$27)+(D34*$G$28)+(E34*$G$29) -> 0.7
A35: M | B35: 1 | C35: 1 | D35: =1/2 -> 0.5 | E35: =1/2 -> 0.5 | F35: =(B35*$G$26)+(C35*$G$27)+(D35*$G$28)+(E35*$G$29) -> 0.7
A36: R | B36: 2 | C36: 2 | D36: 1 | E36: 1 | F36: =(B36*$G$26)+(C36*$G$27)+(D36*$G$28)+(E36*$G$29) -> 1.4
A37: K | B37: 2 | C37: 2 | D37: 1 | E37: 1 | F37: =(B37*$G$26)+(C37*$G$27)+(D37*$G$28)+(E37*$G$29) -> 1.4
A38: JUMLAH | B38: =sum(B34:B37) -> 6 | C38: =sum(C34:C37) -> 6 | D38: =sum(D34:D37) -> 3 | E38: =sum(E34:E37) -> 3
A40: 5. Menghitung Nilai Konsistensi
A41: Lamda Max | B41: =((F34/G26)+(F35/G27)+(F36/G28)+(F37/G29))/4 -> 4.6666667
A42: Cl | B42: =(B41-4)/(4-1) -> 0.22222222
A43: IR | B43: ='MATRIKS PERBANDINGAN'!H17 -> 0.9
A44: CR = CI/IR | B44: =B42/B43 -> 0.24691358

Sheet KAMERA
A2: ALTERNATIF (MEREK) | B2: HARGA | C2: BATERAI (mAh) | D2: RAM (GB) | E2: STORAGE (GB) | F2: KAMERA (MP)
A3: Apple | B3: 2800000 | C3: 6000 | D3: 4 | E3: 64 | F3: 48
A4: Oppo | B4: 2100000 | C4: 5020 | D4: 3 | E4: 64 | F4: 48
A5: Vivo | B5: 2200000 | C5: 5000 | D5: 4 | E5: 128 | F5: 13
A6: Samsung | B6: 2500000 | C6: 4230 | D6: 4 | E6: 128 | F6: 12
A7: Ketentuan: Harga, ROM, RAM, Kamera, Baterai
A9: Matriks
B10: Apple | C10: Oppo | D10: Vivo | E10: Samsung
A11: Apple | B11: 1 | C11: 1 | D11: 3 | E11: 4
A12: Oppo | B12: 1 | C12: 1 | D12: 3 | E12: 4
A13: Vivo | B13: 45717 | C13: 45717 | D13: 1 | E13: 2
A14: Samsung | B14: 45748 | C14: 45748 | D14: 45689 | E14: 1
A16: Matriks Perbandingan
B17: Apple | C17: Oppo | D17: Vivo | E17: Samsung
A18: Apple | B18: 1 | C18: 1 | D18: 3 | E18: 4
A19: Oppo | B19: 1 | C19: 1 | D19: 3 | E19: 4
A20: Vivo | B20: =1/3 -> 0.33333333 | C20: =1/3 -> 0.33333333 | D20: 1 | E20: 2
A21: Samsung | B21: =1/4 -> 0.25 | C21: =1/4 -> 0.25 | D21: =1/2 -> 0.5 | E21: 1
A22: Jumlah | B22: =sum(B18:B21) -> 2.5833333 | C22: =sum(C18:C21) -> 2.5833333 | D22: =sum(D18:D21) -> 7.5 | E22: =sum(E18:E21) -> 11
A24: Menentukan Nilai Eigen dengan membagi setiap matrix dengan jumlah
B25: Apple | C25: Oppo | D25: Vivo | E25: Samsung | F25: Jumlah | G25: Rata-rata nilai eigen
A26: Apple | B26: =B18/$B$22 -> 0.38709677 | C26: =C18/$C$22 -> 0.38709677 | D26: =D18/$D$22 -> 0.4 | E26: =E18/$E$22 -> 0.36363636 | F26: =sum(B26:E26) -> 1.5378299 | G26: =AVERAGE(B26:E26) -> 0.38445748
A27: Oppo | B27: =B19/$B$22 -> 0.38709677 | C27: =C19/$C$22 -> 0.38709677 | D27: =D19/$D$22 -> 0.4 | E27: =E19/$E$22 -> 0.36363636 | F27: =sum(B27:E27) -> 1.5378299 | G27: =AVERAGE(B27:E27) -> 0.38445748
A28: Vivo | B28: =B20/$B$22 -> 0.12903226 | C28: =C20/$C$22 -> 0.12903226 | D28: =D20/$D$22 -> 0.13333333 | E28: =E20/$E$22 -> 0.18181818 | F28: =sum(B28:E28) -> 0.57321603 | G28: =AVERAGE(B28:E28) -> 0.14330401
A29: Samsung | B29: =B21/$B$22 -> 0.096774194 | C29: =C21/C22 -> 0.096774194 | D29: =D21/$D$22 -> 0.066666667 | E29: =E21/$E$22 -> 0.090909091 | F29: =sum(B29:E29) -> 0.35112414 | G29: =AVERAGE(B29:E29) -> 0.087781036
A30: JUMLAH | B30: =sum(B26:B29) -> 1 | C30: =sum(C26:C29) -> 1 | D30: =sum(D26:D29) -> 1 | E30: =sum(E26:E29) -> 1 | F30: =sum(B30:E30) -> 4 | G30: =AVERAGE(B30:E30) -> 1
A32: Normalisasi Nilai Konsistensi (CI)
B33: Apple | C33: Oppo | D33: Vivo | E33: Samsung | F33: Jumlah
A34: H | B34: 1 | C34: 1 | D34: 3 | E34: 4 | F34: =(B34*$G$26)+(C34*$G$27)+(D34*$G$28)+(E34*$G$29) -> 1.5499511
A35: M | B35: 1 | C35: 1 | D35: 3 | E35: 4 | F35: =(B35*$G$26)+(C35*$G$27)+(D35*$G$28)+(E35*$G$29) -> 1.5499511
A36: R | B36: =1/3 -> 0.33333333 | C36: =1/3 -> 0.33333333 | D36: 1 | E36: 2 | F36: =(B36*$G$26)+(C36*$G$27)+(D36*$G$28)+(E36*$G$29) -> 0.57517107
A37: K | B37: =1/4 -> 0.25 | C37: =1/4 -> 0.25 | D37: =1/2 -> 0.5 | E37: 1 | F37: =(B37*$G$26)+(C37*$G$27)+(D37*$G$28)+(E37*$G$29) -> 0.35166178
A38: JUMLAH | B38: =sum(B34:B37) -> 2.5833333 | C38: =sum(C34:C37) -> 2.5833333 | D38: =sum(D34:D37) -> 7.5 | E38: =sum(E34:E37) -> 11
A40: 5. Menghitung Nilai Konsistensi
A41: Lamda Max | B41: =((F34/G26)+(F35/G27)+(F36/G28)+(F37/G29))/4 -> 4.0207059
A42: Cl | B42: =(B41-4)/(4-1) -> 0.0069019565
A43: IR | B43: ='MATRIKS PERBANDINGAN'!H17 -> 0.9
A44: CR = CI/IR | B44: =B42/B43 -> 0.0076688405

Sheet BATERAI
A2: ALTERNATIF (MEREK) | B2: HARGA | C2: BATERAI (mAh) | D2: RAM (GB) | E2: STORAGE (GB) | F2: KAMERA (MP)
A3: Apple | B3: 2800000 | C3: 6000 | D3: 4 | E3: 64 | F3: 48
A4: Oppo | B4: 2100000 | C4: 5020 | D4: 3 | E4: 64 | F4: 48
A5: Vivo | B5: 2200000 | C5: 5000 | D5: 4 | E5: 128 | F5: 13
A6: Samsung | B6: 2500000 | C6: 4230 | D6: 4 | E6: 128 | F6: 12
A7: Ketentuan: Harga, ROM, RAM, Kamera, Baterai
A9: Matriks
B10: Apple | C10: Oppo | D10: Vivo | E10: Samsung
A11: Apple | B11: 1 | C11: 3 | D11: 5 | E11: 7
A12: Oppo | B12: 45717 | C12: 1 | D12: 3 | E12: 5
A13: Vivo | B13: 45778 | C13: 45717 | D13: 1 | E13: 3
A14: Samsung | B14: 45839 | C14: 45778 | D14: 45717 | E14: 1
A16: Matriks Perbandingan
B17: Apple | C17: Oppo | D17: Vivo | E17: Samsung
A18: Apple | B18: 1 | C18: 3 | D18: 5 | E18: 7
A19: Oppo | B19: =1/3 -> 0.33333333 | C19: 1 | D19: 3 | E19: 5
A20: Vivo | B20: =1/5 -> 0.2 | C20: =1/3 -> 0.33333333 | D20: 1 | E20: 3
A21: Samsung | B21: =1/7 -> 0.14285714 | C21: =1/5 -> 0.2 | D21: =1/3 -> 0.33333333 | E21: 1
A22: Jumlah | B22: =sum(B18:B21) -> 1.6761905 | C22: =sum(C18:C21) -> 4.5333333 | D22: =sum(D18:D21) -> 9.3333333 | E22: =sum(E18:E21) -> 16
A24: Menentukan Nilai Eigen dengan membagi setiap matrix dengan jumlah
B25: Apple | C25: Oppo | D25: Vivo | E25: Samsung | F25: Jumlah | G25: Rata-rata nilai eigen
A26: Apple | B26: =B18/$B$22 -> 0.59659091 | C26: =C18/$C$22 -> 0.66176471 | D26: =D18/$D$22 -> 0.53571429 | E26: =E18/$E$22 -> 0.4375 | F26: =sum(B26:E26) -> 2.2315699 | G26: =AVERAGE(B26:E26) -> 0.55789248
A27: Oppo | B27: =B19/$B$22 -> 0.19886364 | C27: =C19/$C$22 -> 0.22058824 | D27: =D19/$D$22 -> 0.32142857 | E27: =E19/$E$22 -> 0.3125 | F27: =sum(B27:E27) -> 1.0533804 | G27: =AVERAGE(B27:E27) -> 0.26334511
A28: Vivo | B28: =B20/$B$22 -> 0.11931818 | C28: =C20/$C$22 -> 0.073529412 | D28: =D20/$D$22 -> 0.10714286 | E28: =E20/$E$22 -> 0.1875 | F28: =sum(B28:E28) -> 0.48749045 | G28: =AVERAGE(B28:E28) -> 0.12187261
A29: Samsung | B29: =B21/$B$22 -> 0.085227273 | C29: =C21/C22 -> 0.044117647 | D29: =D21/$D$22 -> 0.035714286 | E29: =E21/$E$22 -> 0.0625 | F29: =sum(B29:E29) -> 0.22755921 | G29: =AVERAGE(B29:E29) -> 0.056889801
A30: JUMLAH | B30: =sum(B26:B29) -> 1 | C30: =sum(C26:C29) -> 1 | D30: =sum(D26:D29) -> 1 | E30: =sum(E26:E29) -> 1 | F30: =sum(B30:E30) -> 4 | G30: =AVERAGE(B30:E30) -> 1
A32: Normalisasi Nilai Konsistensi (CI)
B33: Apple | C33: Oppo | D33: Vivo | E33: Samsung | F33: Jumlah
A34: H | B34: 1 | C34: 3 | D34: 5 | E34: 7 | F34: =(B34*$G$26)+(C34*$G$27)+(D34*$G$28)+(E34*$G$29) -> 2.3555195
A35: M | B35: =1/3 -> 0.33333333 | C35: 1 | D35: 3 | E35: 5 | F35: =(B35*$G$26)+(C35*$G$27)+(D35*$G$28)+(E35*$G$29) -> 1.0993761
A36: R | B36: =1/5 -> 0.2 | C36: =1/3 -> 0.33333333 | D36: 1 | E36: 3 | F36: =(B36*$G$26)+(C36*$G$27)+(D36*$G$28)+(E36*$G$29) -> 0.49190222
A37: K | B37: =1/7 -> 0.14285714 | C37: =1/5 -> 0.2 | D37: =1/3 -> 0.33333333 | E37: 1 | F37: =(B37*$G$26)+(C37*$G$27)+(D37*$G$28)+(E37*$G$29) -> 0.22988195
A38: JUMLAH | B38: =sum(B34:B37) -> 1.6761905 | C38: =sum(C34:C37) -> 4.5333333 | D38: =sum(D34:D37) -> 9.3333333 | E38: =sum(E34:E37) -> 16
A40: 5. Menghitung Nilai Konsistensi
A41: Lamda Max | B41: =((F34/G26)+(F35/G27)+(F36/G28)+(F37/G29))/4 -> 4.1184657
A42: Cl | B42: =(B41-4)/(4-1) -> 0.039488555
A43: IR | B43: ='MATRIKS PERBANDINGAN'!H17 -> 0.9
A44: CR = CI/IR | B44: =B42/B43 -> 0.043876172

Sheet AKHIR
A2: ALTERNATIF (MEREK) | B2: HARGA | C2: MEMORI | D2: RAM (GB) | E2: KAMERA | F2: BATERAI | G2: KRITERIA UTAMA | H2: HASIL AKHIR | I2: RANKING
A3: Apple | B3: =HARGA!G26 -> 0.05604657 | C3: =MEMORY!G26 -> 0.16666667 | D3: =RAM!G26 -> 0.3 | E3: =KAMERA!G26 -> 0.38445748 | F3: =BATERAI!G26 -> 0.55789248 | G3: ='KRITERIA UTAMA'!H27 -> 0.49617555 | H3: =(B3*$G$3)+(C3*$G$4)+(D3*$G$5)+(E3*$G$6)+(F3*$G$7) -> 0.23603654 | I3: 3
A4: Oppo | B4: =HARGA!G27 -> 0.47457707 | C4: =MEMORY!G27 -> 0.14583333 | D4: =RAM!G27 -> 0.1 | E4: =KAMERA!G27 -> 0.38445748 | F4: =BATERAI!G27 -> 0.26334511 | G4: ='KRITERIA UTAMA'!H28 -> 0.088568443 | H4: =(B4*$G$3)+(C4*$G$4)+(D4*$G$5)+(E4*$G$6)+(F4*$G$7) -> 0.35400492 | I4: 1
A5: Vivo | B5: =HARGA!G28 -> 0.3251896 | C5: =MEMORY!G28 -> 0.29166667 | D5: =RAM!G28 -> 0.3 | E5: =KAMERA!G28 -> 0.14330401 | F5: =BATERAI!G28 -> 0.12187261 | G5: ='KRITERIA UTAMA'!H29 -> 0.088568443 | H5: =(B5*$G$3)+(C5*$G$4)+(D5*$G$5)+(E5*$G$6)+(F5*$G$7) -> 0.25546654 | I5: 2
A6: Samsung | B6: =HARGA!G29 -> 0.14418675 | C6: =MEMORY!G29 -> 0.29166667 | D6: =RAM!G29 -> 0.3 | E6: =KAMERA!G29 -> 0.087781036 | F6: =BATERAI!G29 -> 0.056889801 | G6: ='KRITERIA UTAMA'!H30 -> 0.088568443 | H6: =(B6*$G$3)+(C6*$G$4)+(D6*$G$5)+(E6*$G$6)+(F6*$G$7) -> 0.14526612 | I6: 4
A7: Ketentuan: Harga, ROM, RAM, Kamera, Baterai | G7: ='KRITERIA UTAMA'!H31 -> 0.23811912 | H7: =(B7*$G$3)+(C7*$G$4)+(D7*$G$5)+(E7*$G$6)+(F7*$G$7) -> 0
